Workbook

Sheet General
B1: Analysis of execution time in the three methods
C2: P1 | D2: P2 | E2: P3 | F2: P4 | G2: P5 | H2: P6 (p1) | I2: P6(p2) | J2: P7 | K2: Average
B3: Bounding Box | C3: =BoundingBox!R10 -> 0.3325 | D3: =BoundingBox!R23 -> 1.16 | E3: =BoundingBox!R33 -> 0.70333333 | F3: =BoundingBox!R42 -> 0.55666667 | G3: =BoundingBox!R53 -> 0.28333333 | H3: =BoundingBox!R63 -> 0.32666667 | I3: =BoundingBox!Z63 -> 0.73333333 | J3: =BoundingBox!R73 -> 1.8866667 | K3: =AVERAGE(C3:J3) -> 0.7478125
B4: Convex Hull | C4: =ConvexHull!R9 -> 0.53 | D4: =ConvexHull!R22 -> 1.0466667 | E4: =ConvexHull!R32 -> 0.80666667 | F4: =ConvexHull!R41 -> 0.65 | G4: =ConvexHull!R52 -> 0.4575 | H4: =ConvexHull!R62 -> 0.85666667 | I4: =ConvexHull!Y62 -> 1.6225 | J4: =ConvexHull!R72 -> 2.55 | K4: =AVERAGE(C4:J4) -> 1.065
B5: Voxelization | C5: =Voxelization!R9 -> 6.2133333 | D5: =Voxelization!R22 -> 5.7066667 | E5: =Voxelization!R32 -> 11.743333 | F5: =Voxelization!R41 -> 5.3433333 | G5: =Voxelization!R52 -> 3.6933333 | H5: =Voxelization!R62 -> 2.49 | I5: =Voxelization!Y62 -> 12.316667 | J5: =Voxelization!R72 -> 17.003333 | K5: =AVERAGE(C5:J5) -> 8.06375
B28: Analysis of the number of points in the cloud using the three methods.
C29: P1 | D29: P2 | E29: P3 | F29: P4 | G29: P5 | H29: P6 | I29: P6(p2) | J29: P7 | K29: Average
B30: Bounding Box | C30: =BoundingBox!R15 -> 593.75 | D30: =BoundingBox!R28 -> 1188 | E30: =BoundingBox!R38 -> 1252 | F30: =BoundingBox!R47 -> 398.33333 | G30: =BoundingBox!R58 -> 406.33333 | H30: =BoundingBox!R68 -> 350.33333 | I30: =BoundingBox!Z68 -> 944.33333 | J30: =BoundingBox!R78 -> 2153.3333 | K30: =AVERAGE(C30:J30) -> 910.80208
B31: Convex Hull | C31: =ConvexHull!R14 -> 724 | D31: =ConvexHull!R27 -> 1127.3333 | E31: =ConvexHull!R37 -> 1380.6667 | F31: =ConvexHull!R46 -> 457 | G31: =ConvexHull!R57 -> 579 | H31: =ConvexHull!R67 -> 1171 | I31: =ConvexHull!Y67 -> 1434 | J31: =ConvexHull!R77 -> 2215 | K31: =AVERAGE(C31:J31) -> 1136
B32: Voxelization | C32: =Voxelization!R14 -> 1357.6667 | D32: =Voxelization!R27 -> 2004.6667 | E32: =Voxelization!R37 -> 2743.5 | F32: =Voxelization!R46 -> 850 | G32: =Voxelization!R57 -> 1047 | H32: =Voxelization!R67 -> 1496 | I32: =Voxelization!Y67 -> 2219 | J32: =Voxelization!R77 -> 3371 | K32: =AVERAGE(C32:J32) -> 1886.1042
C55: Average percentage of correct and incorrect measurements of the volume of rectangular and cubic boxes.
D56: Pct1 | E56: Pct3 | F56: Pct5 | G56: Pct7 | H56: MAPE | I56: RMSE (L)
C57: Bounding Box | D57: =BoundingBox!R11 -> 0.06364125 | E57: =BoundingBox!R34 -> 0.128227 | F57: =BoundingBox!R54 -> 0.034780667 | G57: =BoundingBox!R74 -> 0.055640333 | H57: =BoundingBox!Q85 -> 0.020467281 | I57: =BoundingBox!S85*1000 -> 1.575356
C58: Convex Hull | D58: =ConvexHull!R10 -> 0.066232 | E58: =ConvexHull!R33 -> 0.12816833 | F58: =ConvexHull!R53 -> 0.0333815 | G58: =ConvexHull!R73 -> 0.054172333 | H58: =ConvexHull!Q84 -> 0.022679639 | I58: =ConvexHull!S84*1000 -> 1.4213688
C59: Voxelization | D59: =Voxelization!R10 -> 0.063874333 | E59: =Voxelization!R33 -> 0.12800733 | F59: =Voxelization!R53 -> 0.033699667 | G59: =Voxelization!R73 -> 0.05106 | H59: =Voxelization!Q84 -> 0.036367092 | I59: =Voxelization!S84*1000 -> 2.7586407
C62: Average percentage of correct and incorrect measurements of the volume of packages with irregular shapes.
D63: Pct2 | E63: Pct4 | F63: Pct6 (Pos1) | G63: Pct6 (Pos2) | H63: MAPE | I63: RMSE
C64: Bounding Box | D64: =BoundingBox!R24 -> 0.043492 | E64: =BoundingBox!R43 -> 0.011974333 | F64: =BoundingBox!R64 -> 0.039687333 | G64: =BoundingBox!Z64 -> 0.078424333 | H64: =BoundingBox!Q95 -> 0.16110941 | I64: =BoundingBox!S95*1000 -> 20.167394 | J64: =BoundingBox!S71 | K64: =BoundingBox!S81 | L64: =BoundingBox!O92
C65: Convex Hull | D65: =ConvexHull!R23 -> 0.034340333 | E65: =ConvexHull!R42 -> 0.01241825 | F65: =ConvexHull!R63 -> 0.083702667 | G65: =ConvexHull!Y63 -> 0.0714745 | H65: =ConvexHull!Q94 -> 0.094879093 | I65: =ConvexHull!S94*1000 -> 5.8434054 | J65: =ConvexHull!S70 | K65: =ConvexHull!S80 | L65: =ConvexHull!O91
C66: Voxelization | D66: =Voxelization!R23 -> 0.034187667 | E66: =Voxelization!R42 -> 0.012085 | F66: =Voxelization!R63 -> 0.078293667 | G66: =Voxelization!Y63 -> 0.058409667 | H66: =Voxelization!Q94 -> 0.12468737 | I66: =Voxelization!S94*1000 -> 10.756164 | J66: =Voxelization!S70 | K66: =Voxelization!S80 | L66: =Voxelization!O91
C70: RMSE of dimensions and volume calculation in regular packages
D71: Length (m) | E71: Width (m) | F71: Height (m) | G71: Top Sensor Distance (m)
C72: Bounding Box | D72: =BoundingBox!$S86 -> 0.032202484 | E72: =BoundingBox!$S87 -> 0.053691426 | F72: =BoundingBox!$S88 -> 0.035537629 | G72: =BoundingBox!$S89 -> 0.035537629
C73: Convex Hull | D73: =ConvexHull!$S85 -> 0.041567369 | E73: =ConvexHull!$S86 -> 0.057306195 | F73: =ConvexHull!$S87 -> 0.02233142 | G73: =ConvexHull!$S88 -> 0.02233142
C74: Voxelization | D74: =Voxelization!$S85 -> 0.060086743 | E74: =Voxelization!$S86 -> 0.057172983 | F74: =Voxelization!$S87 -> 0.016355427 | G74: =Voxelization!$S88 -> 0.016355427
C76: RMSE of dimensions and volume calculation in irregular packages
D77: Length (m) | E77: Width (m) | F77: Height (m) | G77: Top Sensor Distance (m)
C78: Bounding Box | D78: =BoundingBox!$S96 -> 0.11547294 | E78: =BoundingBox!$S97 -> 0.023977262 | F78: =BoundingBox!$S98 -> 0.010744978 | G78: =BoundingBox!$S99 -> 0.010744978
C79: Convex Hull | D79: =ConvexHull!$S95 -> 0.03799154 | E79: =ConvexHull!$S96 -> 0.044829837 | F79: =ConvexHull!$S97 -> 0.013296079 | G79: =ConvexHull!$S98 -> 0.013296079
C80: Voxelization | D80: =Voxelization!$S95 -> 0.044581386 | E80: =Voxelization!$S96 -> 0.077068692 | F80: =Voxelization!$S97 -> 0.01839384 | G80: =Voxelization!$S98 -> 0.01839384
C84: RMSE GENERAL
D85: Length (m) | E85: Width (m) | F85: Height (m) | G85: Top Sensor Distance (m)
C86: Bounding Box | D86: =BoundingBox!$W88 -> 0.081689198 | E86: =BoundingBox!$W89 -> 0.042720019 | F86: =BoundingBox!$W90 -> 0.027147744 | G86: =BoundingBox!$W91 -> 0.027147744
C87: Convex Hull | D87: =ConvexHull!$W87 -> 0.039753407 | E87: =ConvexHull!$W88 -> 0.051217763 | F87: =ConvexHull!$W89 -> 0.018214768 | G87: =ConvexHull!$W90 -> 0.018214768
C88: Voxelization | D88: =Voxelization!$W87 -> 0.052905182 | E88: =Voxelization!$W88 -> 0.06785401 | F88: =Voxelization!$W89 -> 0.017404501 | G88: =Voxelization!$W90 -> 0.017404501

Sheet BoundingBox
A2: Test sequence for calculating packet volume
A6: Testing with the Bounding Box Volume Estimation algorithm
A7: Note: The criterion used to identify the calculated volume as valid for rectangular and cubic boxes was that it was close to the value of the manually calculated volume.
Q8: Average dimensions
A9: Package Type | B9: Example of output from a valid test. | G9: Measurements Package 1 | O9: Manual measurement (m) | Q9: Algorithm Results | R9: averages | S9: Percentage of correct answers | T9: Difference between manual measurement and algorithmic measurement. | V9: absolute percentage error volume (APE)
A10: Package 1 | B10: Object identified with 596 points. Estimated volume of the OBB: 0.013 m³ Dimensions of the identified object: Length: 0.452 m Width: 0.312 m Height: 0.456 m Volume: 0.064272 m³ Total execution time: 0.31 seconds | F10: Tests | G10: Time | H10: Volume | I10: Number of points | J10: Length | K10: Width | L10: Height | M10: TSDs | N10: VolumePCT1 (m³) | O10: =0.485*0.275*0.495 -> 0.066020625 | Q10: Execution time (s) | R10: =G16 -> 0.3325
F11: 1 | G11: 0.38 | H11: 0.06356 | I11: 635 | J11: 0.43 | K11: 0.327 | L11: 0.452 | M11: =1.55-L11-0.1 -> 0.998 | N11: Length (m) | O11: 0.485 | Q11: Volume (m³) | R11: =H16 -> 0.06364125 | S11: =R11/O10 -> 0.96396013 | T11: =O10-R11 -> 0.002379375 | V11: =(ABS(H11-O10)/O10+ABS(H12-O10)/O10+ABS(H13-O10)/O10+ABS(H14-O10)/O10) -> 0.1441595
F12: 2 | G12: 0.31 | H12: 0.064272 | I12: 596 | J12: 0.452 | K12: 0.312 | L12: 0.456 | M12: =1.55-L12-0.1 -> 0.994 | N12: Width (m) | O12: 0.275 | Q12: Length (m) | R12: =J16 -> 0.44675 | S12: =R12/O11 -> 0.92113402 | T12: =O11-R12 -> 0.03825
F13: 3 | G13: 0.29 | H13: 0.062734 | I13: 592 | J13: 0.446 | K13: 0.301 | L13: 0.467 | M13: =1.55-L13-0.1 -> 0.983 | N13: Height (m) | O13: 0.495 | Q13: Width (m) | R13: =K16 -> 0.31225 | S13: =R13/O12 -> 1.1354545 | T13: =O12-R13 -> -0.03725
F14: 4 | G14: 0.35 | H14: 0.063999 | I14: 552 | J14: 0.459 | K14: 0.309 | L14: 0.451 | M14: =1.55-L14-0.1 -> 0.999 | N14: Top Sensor Distance (TSD) | O14: =1.55 -0.495-0.1 -> 0.955 | Q14: Height (m) | R14: =L16 -> 0.4565 | S14: =R14/O13 -> 0.92222222 | T14: =O13-R14 -> 0.0385
F15: 5 | Q15: Number of points | R15: =I16 -> 593.75
F16: average | G16: =AVERAGEA(G11:G14) -> 0.3325 | H16: =AVERAGEA(H11:H14) -> 0.06364125 | I16: =AVERAGEA(I11:I14) -> 593.75 | J16: =AVERAGEA(J11:J14) -> 0.44675 | K16: =AVERAGEA(K11:K14) -> 0.31225 | L16: =AVERAGEA(L11:L14) -> 0.4565 | M16: =AVERAGEA(M11:M14) -> 0.9935 | Q16: Top Sensor Distance (TSD) | R16: =M16 -> 0.9935 | S16: =R16/O14 -> 1.0403141 | T16: =O14-R16 -> -0.0385
F17: Accuracy % | H17: =H16/O10 -> 0.96396013 | J17: =J16/O11 -> 0.92113402 | K17: =K16/O12 -> 1.1354545 | L17: =L16/O13 -> 0.92222222 | M17: =M16/O14 -> 1.0403141
F18: Error square | H18: =SUM((H11-O10)^2,(H12-O10)^2,(H13-O10)^2,(H14-O10)^2) -> 2.4001236e-05 | J18: =SUM((J11-$O11)^2,(J12-$O11)^2,(J13-$O11)^2,(J14-$O11)^2) -> 0.006311 | K18: =SUM((K11-$O12)^2,(K12-$O12)^2,(K13-$O12)^2,(K14-$O12)^2) -> 0.005905 | L18: =SUM((L11-$O13)^2,(L12-$O13)^2,(L13-$O13)^2,(L14-$O13)^2) -> 0.00609 | M18: =SUM((M11-$O14)^2,(M12-$O14)^2,(M13-$O14)^2,(M14-$O14)^2) -> 0.00609
A20: Package Type | B20: Example of output from a valid test. | G20: Measurements Package 2
A21: Package 2 | B21: Object identified with 1199 points. Estimated volume of the OBB: 0.036 m³ Dimensions of the identified object: Length: 0.492 m Width: 0.440 m Height: 0.197 m Volume: 0.042596 m³ Total execution time: 1.35 seconds | F21: Tests | G21: Time | H21: Volume | I21: Number of points | J21: Length | K21: Width | L21: Height | M21: TSDs
F22: 1 | G22: 1.35 | H22: 0.042596 | I22: 1199 | J22: 0.492 | K22: 0.44 | L22: 0.197 | M22: =1.55-L22-0.1 -> 1.253 | O22: Manual measurement | Q22: Algorithm Results | R22: averages | S22: Percentage of correct answers | T22: Difference between manual measurement and algorithmic measurement. | V22: absolute percentage error volume (APE)
F23: 2 | G23: 0.97 | H23: 0.044388 | I23: 1177 | J23: 0.492 | K23: 0.432 | L23: 0.209 | M23: =1.55-L23-0.1 -> 1.241 | N23: PCT2 Volume (m2) | O23: =0.44*0.46*0.21 -> 0.042504 | Q23: Execution time (s) | R23: =G27 -> 1.16
F24: 3 | N24: Length (m) | O24: 0.46 | Q24: Volume (m³) | R24: =H27 -> 0.043492 | S24: =R24/O23 -> 1.0232449 | T24: =O23-R24 -> -0.000988 | V24: =(ABS(H22-O23)/O23+ABS(H23-O23)/O23) -> 0.046489742
F25: 4 | N25: Width (m) | O25: 0.44 | Q25: Length (m) | R25: =J27 -> 0.492 | S25: =R25/O24 -> 1.0695652 | T25: =O24-R25 -> -0.032
F26: 5 | N26: Height (m) | O26: 0.21 | Q26: Width (m) | R26: =K27 -> 0.436 | S26: =R26/O25 -> 0.99090909 | T26: =O25-R26 -> 0.004
F27: average | G27: =AVERAGEA(G22:G25) -> 1.16 | H27: =AVERAGEA(H22:H25) -> 0.043492 | I27: =AVERAGEA(I22:I25) -> 1188 | J27: =AVERAGEA(J22:J25) -> 0.492 | K27: =AVERAGEA(K22:K25) -> 0.436 | L27: =AVERAGEA(L22:L25) -> 0.203 | M27: =AVERAGEA(M22:M25) -> 1.247 | N27: Top Sensor Distance (TSD) | O27: =1.55-O26-0.1 -> 1.24 | Q27: Height (m) | R27: =L27 -> 0.203 | S27: =R27/O26 -> 0.96666667 | T27: =O26-R27 -> 0.007
F28: Accuracy % | H28: =H27/O23 -> 1.0232449 | J28: =J27/O24 -> 1.0695652 | K28: =K27/O25 -> 0.99090909 | L28: =L27/O26 -> 0.96666667 | M28: =M27/O27 -> 1.0056452 | Q28: Number of points | R28: =I27 -> 1188
F29: Error square | H29: =SUM((H22-$O23)^2,(H23-$O23)^2) -> 3.55792e-06 | J29: =SUM((J22-$O24)^2,(J23-$O24)^2) -> 0.002048 | K29: =SUM((K22-$O25)^2,(K23-$O25)^2) -> 6.4e-05 | L29: =SUM((L22-$O26)^2,(L23-$O26)^2) -> 0.00017 | M29: =SUM((M22-$O27)^2,(M23-$O27)^2) -> 0.00017 | Q29: Top Sensor Distance (TSD) | R29: =1.55-R27-0.1 -> 1.247 | S29: =R29/O27 -> 1.0056452 | T29: =O27-R29 -> -0.007
A31: Package Type | B31: Example of output from a valid test. | G31: Measurements Package 3
A32: Package 3 | B32: Object identified with 1194 points. Estimated volume of the OBB: 0.026 m³ Dimensions of the identified object: Length: 0.522 m Width: 0.520 m Height: 0.472 m Volume: 0.128076 m³ Total execution time: 0.64 seconds Successful attempt! Volume within standard range. | F32: Tests | G32: Time | H32: Volume | I32: Number of points | J32: Length | K32: Width | L32: Height | M32: TSDs | O32: Manual measurement | Q32: Algorithm Results | R32: averages | S32: Percentage of correct answers | T32: Difference between manual measurement and algorithmic measurement. | V32: absolute percentage error volume (APE)
F33: 1 | G33: 0.78 | H33: 0.127857 | I33: 1292 | J33: 0.522 | K33: 0.52 | L33: 0.471 | M33: =1.55-L33-0.1 -> 0.979 | N33: PCT3 Volume (m³) | O33: =0.505*0.505*0.505 -> 0.12878762 | Q33: Execution time (s) | R33: =G38 -> 0.70333333
F34: 2 | G34: 0.69 | H34: 0.128748 | I34: 1270 | J34: 0.53 | K34: 0.514 | L34: 0.473 | M34: =1.55-L34-0.1 -> 0.977 | N34: Length (m) | O34: 0.505 | Q34: Volume (m³) | R34: =H38 -> 0.128227 | S34: =R34/O33 -> 0.9956469 | T34: =O33-R34 -> 0.000560625 | V34: =(ABS(H33-O33)/O33+ABS(H34-O33)/O33+ABS(H35-O33)/O33) -> 0.01305929
F35: 3 | G35: 0.64 | H35: 0.128076 | I35: 1194 | J35: 0.522 | K35: 0.52 | L35: 0.472 | M35: =1.55-L35-0.1 -> 0.978 | N35: Width (m) | O35: 0.505 | Q35: Length (m) | R35: =J38 -> 0.52466667 | S35: =R35/O34 -> 1.0389439 | T35: =O34-R35 -> -0.019666667
F36: 4 | N36: Height (m) | O36: 0.505 | Q36: Width (m) | R36: =K38 -> 0.518 | S36: =R36/O35 -> 1.0257426 | T36: =O35-R36 -> -0.013
F37: 5 | N37: Top Sensor Distance (TSD) | O37: =1.55-O36-0.1 -> 0.945 | Q37: Height (m) | R37: =L35 -> 0.472 | S37: =R37/O36 -> 0.93465347 | T37: =O36-R37 -> 0.033
F38: average | G38: =AVERAGEA(G33:G36) -> 0.70333333 | H38: =AVERAGEA(H33:H36) -> 0.128227 | I38: =AVERAGEA(I33:I36) -> 1252 | J38: =AVERAGEA(J33:J36) -> 0.52466667 | K38: =AVERAGEA(K33:K36) -> 0.518 | L38: =AVERAGEA(L33:L36) -> 0.472 | M38: =AVERAGEA(M33:M36) -> 0.978 | Q38: Number of points | R38: =I38 -> 1252
F39: Accuracy % | H39: =H38/O33 -> 0.9956469 | J39: =J38/O34 -> 1.0389439 | K39: =K38/O35 -> 1.0257426 | L39: =L38/O36 -> 0.93465347 | M39: =M38/O37 -> 1.0349206 | Q39: Top Sensor Distance (TSD) | R39: =M38 -> 0.978 | S39: =R39/O37 -> 1.0349206 | T39: =O37-R39 -> -0.033
F40: Error square | H40: =SUM((H33-O33)^2,(H34-O33)^2,(H35-O33)^2) -> 1.3740432e-06 | J40: =SUM((J33-$O34)^2,(J34-$O34)^2,(J35-$O34)^2) -> 0.001203 | K40: =SUM((K33-$O35)^2,(K34-$O35)^2,(K35-$O35)^2) -> 0.000531 | L40: =SUM((L33-$O36)^2,(L34-$O36)^2,(L35-$O36)^2) -> 0.003269 | M40: =SUM((M33-$O37)^2,(M34-$O37)^2,(M35-$O37)^2) -> 0.003269
O41: Manual measurement | Q41: Algorithm Results | S41: Percentage of correct answers | T41: Difference between manual measurement and algorithmic measurement. | V41: absolute percentage error volume (APE)
A42: Package Type | B42: Example of output from a valid test. | G42: Measurements Package 4 | N42: PCT4 Volume (m³) | O42: =0.51*0.16*0.155 -> 0.012648 | Q42: Execution time (s) | R42: =G49 -> 0.55666667
A43: Package 4 | B43: Object identified with 427 points. Estimated volume of the OBB: 0.009 m³ Dimensions of the identified object: Length: 0.479 m Width: 0.188 m Height: 0.144 m Volume: 0.012921 m³ Total execution time: 0.65 seconds Successful attempt! Volume within standard range. | F43: Tests | G43: Time | H43: Volume | I43: Number of points | J43: Length | K43: Width | L43: Height | M43: TSDs | N43: Length (m) | O43: 0.51 | Q43: Volume (m³) | R43: =H49 -> 0.011974333 | S43: =R43/O42 -> 0.9467373 | T43: =O42-R43 -> 0.00067366667 | V43: =(ABS(H44-O42)/O42+ABS(H45-O42)/O42+ABS(H46-O42)/O42) -> 0.20295699
F44: 1 | G44: 0.45 | H44: 0.011823 | I44: 382 | J44: 0.488 | K44: 0.174 | L44: 0.14 | M44: =1.55-L44-0.1 -> 1.31 | N44: Width (m) | O44: 0.16 | Q44: Length (m) | R44: =J49 -> 0.46133333 | S44: =R44/O43 -> 0.90457516 | T44: =O43-R44 -> 0.048666667
F45: 2 | G45: 0.57 | H45: 0.011179 | I45: 386 | J45: 0.417 | K45: 0.186 | L45: 0.144 | M45: =1.55-L45-0.1 -> 1.306 | N45: Height (m) | O45: 0.155 | Q45: Width (m) | R45: =K49 -> 0.18266667 | S45: =R45/O44 -> 1.1416667 | T45: =O44-R45 -> -0.022666667
F46: 3 | G46: 0.65 | H46: 0.012921 | I46: 427 | J46: 0.479 | K46: 0.188 | L46: 0.144 | M46: =1.55-L46-0.1 -> 1.306 | N46: Top Sensor Distance (TSD) | O46: =1.55-O45-0.1 -> 1.295 | Q46: Height (m) | R46: =K49 -> 0.18266667 | S46: =R46/O45 -> 1.1784946 | T46: =O45-R46 -> -0.027666667
...

Sheet ConvexHull
A2: Test sequence for calculating packet volume
A6: Testing with the Convex Hull Volume Estimation algorithm
A8: Package Type | B8: Example of output from a valid test. | G8: Measurements Package 1 | O8: Manual measurement (m) | Q8: Algorithm Results | R8: averages | S8: Percentage of correct answers | T8: Difference between manual measurement and algorithmic measurement. | V8: absolute percentage error volume (APE)
A9: Package 1 | B9: Starting detection of the complete object with ConvexHull... 1 cluster found. Object identified with 712 points. Total execution time: 0.50 seconds Object dimensions: Length: 0.489 m | Width: 0.301 m | Height: 0.498 m Dimensions (Convex Hull): Base area: 0.130 m² | Height: 0.498 m Total volume: 0.064924 m³ | F9: Tests | G9: Time | H9: Volume | I9: Number of points | J9: Length | K9: Width | L9: Height | M9: TSD | N9: VolumePCT1 (m³) | O9: =0.485*0.275*0.495 -> 0.066020625 | Q9: Execution time (s) | R9: =G15 -> 0.53
F10: 1 | G10: 0.5 | H10: 0.064924 | I10: 712 | J10: 0.489 | K10: 0.301 | L10: 0.498 | M10: =1.55-L10-0.1 -> 0.952 | N10: Length (m) | O10: 0.485 | Q10: Volume (m³) | R10: =H15 -> 0.066232 | S10: =R10/O9 -> 1.0032017 | T10: =O9-R10 -> -0.000211375 | V10: =(ABS(H10-O9)/O9+ABS(H11-O9)/O9+ABS(H12-O9)/O9) -> 0.04781271
F11: 2 | G11: 0.54 | H11: 0.067916 | I11: 731 | J11: 0.511 | K11: 0.308 | L11: 0.498 | M11: =1.55-L11-0.1 -> 0.952 | N11: Width (m) | O11: 0.275 | Q11: Length (m) | R11: =J15 -> 0.49866667 | S11: =R11/O10 -> 1.0281787 | T11: =O10-R11 -> -0.013666667
F12: 3 | G12: 0.55 | H12: 0.065856 | I12: 729 | J12: 0.496 | K12: 0.308 | L12: 0.499 | M12: =1.55-L12-0.1 -> 0.951 | N12: Height (m) | O12: 0.495 | Q12: Width (m) | R12: =K15 -> 0.30566667 | S12: =R12/O11 -> 1.1115152 | T12: =O11-R12 -> -0.030666667
F13: 4 | N13: Top Sensor Distance (TSD) | O13: =1.55-O12-0.1 -> 0.955 | Q13: Height (m) | R13: =L15 -> 0.49833333 | S13: =R13/O12 -> 1.006734 | T13: =O12-R13 -> -0.0033333333
F14: 5 | Q14: Number of points | R14: =I15 -> 724
F15: average | G15: =AVERAGEA(G10:G13) -> 0.53 | H15: =AVERAGEA(H10:H13) -> 0.066232 | I15: =AVERAGEA(I10:I13) -> 724 | J15: =AVERAGEA(J10:J13) -> 0.49866667 | K15: =AVERAGEA(K10:K13) -> 0.30566667 | L15: =AVERAGEA(L10:L13) -> 0.49833333 | M15: =AVERAGEA(M10:M13) -> 0.95166667 | Q15: Top Sensor Distance (TSD) | R15: =M15 -> 0.95166667 | S15: =R15/O13 -> 0.9965096 | T15: =O13-R15 -> 0.0033333333
F16: Accuracy % | H16: =H15/O9 -> 1.0032017 | J16: =J15/O10 -> 1.0281787 | K16: =K15/O11 -> 1.1115152 | L16: =L15/O12 -> 1.006734 | M16: =M15/O13 -> 0.9965096
F17: Error square | H17: =SUM((H10-O9)^2,(H11-O9)^2,(H12-O9)^2) -> 4.8221342e-06 | J17: =SUM((J10-$O10)^2,(J11-$O10)^2,(J12-$O10)^2) -> 0.000813 | K17: =SUM((K10-$O11)^2,(K11-$O11)^2,(K12-$O11)^2) -> 0.002854 | L17: =SUM((L10-$O12)^2,(L11-$O12)^2,(L12-$O12)^2) -> 3.4e-05 | M17: =SUM((M10-$O13)^2,(M11-$O13)^2,(M12-$O13)^2) -> 3.4e-05
A19: Package Type | B19: Example of output from a valid test. | G19: Measurements Package 1
A20: Package 2 | B20: Object identified with 1102 points. Total execution time: 1.05 seconds Object dimensions: Length: 0.476 m | Width: 0.434 m | Height: 0.192 m Dimensions (Convex Hull): Base area: 0.181 m² | Height: 0.192 m Total volume: 0.034646 m³ | F20: Tests | G20: Time | H20: Volume | I20: Number of points | J20: Length | K20: Width | L20: Height | M20: TSD
F21: 1 | G21: 1.05 | H21: 0.034102 | I21: 1139 | J21: 0.48 | K21: 0.431 | L21: 0.192 | M21: =1.55-L21-0.1 -> 1.258 | O21: Manual measurement | Q21: Algorithm Results | R21: averages | S21: Percentage of correct answers | T21: Difference between manual measurement and algorithmic measurement. | V21: absolute percentage error volume (APE)
F22: 2 | G22: 1.04 | H22: 0.034273 | I22: 1141 | J22: 0.473 | K22: 0.434 | L22: 0.19 | M22: =1.55-L22-0.1 -> 1.26 | N22: PCT2 Volume (m2) | O22: =0.44*0.46*0.21 -> 0.042504 | Q22: Execution time (s) | R22: =G26 -> 1.0466667
F23: 3 | G23: 1.05 | H23: 0.034646 | I23: 1102 | J23: 0.476 | K23: 0.434 | L23: 0.192 | M23: =1.55-L23-0.1 -> 1.258 | N23: Length (m) | O23: 0.46 | Q23: Volume (m³) | R23: =H26 -> 0.034340333 | S23: =R23/O22 -> 0.8079318 | T23: =O22-R23 -> 0.0081636667 | V23: =(ABS(H21-O22)/O22+ABS(H22-O22)/O22+ABS(H23-O22)/O22) -> 0.57620459
F24: 4 | N24: Width (m) | O24: 0.44 | Q24: Length (m) | R24: =J26 -> 0.47633333 | S24: =R24/O23 -> 1.0355072 | T24: =O23-R24 -> -0.016333333
F25: 5 | N25: Height (m) | O25: 0.21 | Q25: Width (m) | R25: =K26 -> 0.433 | S25: =R25/O24 -> 0.98409091 | T25: =O24-R25 -> 0.007
F26: average | G26: =AVERAGEA(G21:G24) -> 1.0466667 | H26: =AVERAGEA(H21:H24) -> 0.034340333 | I26: =AVERAGEA(I21:I24) -> 1127.3333 | J26: =AVERAGEA(J21:J24) -> 0.47633333 | K26: =AVERAGEA(K21:K24) -> 0.433 | L26: =AVERAGEA(L21:L24) -> 0.19133333 | M26: =AVERAGEA(M21:M24) -> 1.2586667 | N26: Top Sensor Distance (TSD) | O26: =1.55-O25-0.1 -> 1.24 | Q26: Height (m) | R26: =L26 -> 0.19133333 | S26: =R26/O25 -> 0.91111111 | T26: =O25-R26 -> 0.018666667
F27: Accuracy % | H27: =H26/O22 -> 0.8079318 | J27: =J26/O23 -> 1.0355072 | K27: =K26/O24 -> 0.98409091 | L27: =L26/O25 -> 0.91111111 | M27: =M26/O26 -> 1.0150538 | Q27: Number of points | R27: =I26 -> 1127.3333
F28: Error square | H28: =SUM((H21-$O22)^2,(H22-$O22)^2,(H23-$O22)^2) -> 0.00020009113 | J28: =SUM((J21-$O23)^2,(J22-$O23)^2,(J23-$O23)^2) -> 0.000825 | K28: =SUM((K21-$O24)^2,(K22-$O24)^2,(K23-$O24)^2) -> 0.000153 | L28: =SUM((L21-$O25)^2,(L22-$O25)^2,(L23-$O25)^2) -> 0.001048 | M28: =SUM((M21-$O26)^2,(M22-$O26)^2,(M23-$O26)^2) -> 0.001048 | Q28: Top Sensor Distance (TSD) | R28: =M26 -> 1.2586667 | S28: =R28/O26 -> 1.0150538 | T28: =O26-R28 -> -0.018666667
A30: Package Type | B30: Example of output from a valid test. | G30: Measurements Package 1
A31: Package 3 | B31: 1 cluster found. Object identified with 1332 points. Total execution time: 0.72 seconds Object dimensions: Length: 0.528 m | Width: 0.519 m | Height: 0.494 m Dimensions (Convex Hull): Base area: 0.258 m² | Height: 0.494 m Total volume: 0.127569 m³ Successful attempt! Volume within the standard. | F31: Tests | G31: Time | H31: Volume | I31: Number of points | J31: Length | K31: Width | L31: Height | M31: TSD | O31: Manual measurement | Q31: Algorithm Results | R31: averages | S31: Percentage of correct answers | T31: Difference between manual measurement and algorithmic measurement. | V31: absolute percentage error volume (APE)
F32: 1 | G32: 0.88 | H32: 0.126833 | I32: 1374 | J32: 0.53 | K32: 0.526 | L32: 0.495 | M32: =1.55-L32-0.1 -> 0.955 | N32: PCT3 Volume (m³) | O32: =0.505*0.505*0.505 -> 0.12878762 | Q32: Execution time (s) | R32: =G37 -> 0.80666667
F33: 2 | G33: 0.82 | H33: 0.130103 | I33: 1436 | J33: 0.536 | K33: 0.534 | L33: 0.494 | M33: =1.55-L33-0.1 -> 0.956 | N33: Length (m) | O33: 0.505 | Q33: Volume (m³) | R33: =H37 -> 0.12816833 | S33: =R33/O32 -> 0.99519137 | T33: =O32-R33 -> 0.00061929167 | V33: =(ABS(H32-O32)/O32+ABS(H33-O32)/O32+ABS(H34-O32)/O32) -> 0.034852922
F34: 3 | G34: 0.72 | H34: 0.127569 | I34: 1332 | J34: 0.528 | K34: 0.519 | L34: 0.494 | M34: =1.55-L34-0.1 -> 0.956 | N34: Width (m) | O34: 0.505 | Q34: Length (m) | R34: =J37 -> 0.53133333 | S34: =R34/O33 -> 1.0521452 | T34: =O33-R34 -> -0.026333333
F35: 4 | N35: Height (m) | O35: 0.505 | Q35: Width (m) | R35: =K37 -> 0.52633333 | S35: =R35/O34 -> 1.0422442 | T35: =O34-R35 -> -0.021333333
F36: 5 | N36: Top Sensor Distance (TSD) | O36: =1.55-O35-0.1 -> 0.945 | Q36: Height (m) | R36: =L37 -> 0.49433333 | S36: =R36/O35 -> 0.97887789 | T36: =O35-R36 -> 0.010666667
F37: average | G37: =AVERAGEA(G32:G35) -> 0.80666667 | H37: =AVERAGEA(H32:H35) -> 0.12816833 | I37: =AVERAGEA(I32:I35) -> 1380.6667 | J37: =AVERAGEA(J32:J35) -> 0.53133333 | K37: =AVERAGEA(K32:K35) -> 0.52633333 | L37: =AVERAGEA(L32:L35) -> 0.49433333 | M37: =AVERAGEA(M32:M35) -> 0.95566667 | Q37: Number of points | R37: =I37 -> 1380.6667
F38: Accuracy % | H38: =H37/O32 -> 0.99519137 | J38: =J37/O33 -> 1.0521452 | K38: =K37/O34 -> 1.0422442 | L38: =L37/O35 -> 0.97887789 | M38: =M37/O36 -> 1.0112875 | Q38: Top Sensor Distance (TSD) | R38: =M37 -> 0.95566667 | S38: =R38/O36 -> 1.0112875 | T38: =O36-R38 -> -0.010666667
F39: Error square | H39: =SUM((H32-O32)^2,(H33-O32)^2,(H34-O32)^2) -> 7.0358172e-06 | J39: =SUM((J32-$O33)^2,(J33-$O33)^2,(J34-$O33)^2) -> 0.002115 | K39: =SUM((K32-$O34)^2,(K33-$O34)^2,(K34-$O34)^2) -> 0.001478 | L39: =SUM((L32-$O35)^2,(L33-$O35)^2,(L34-$O35)^2) -> 0.000342 | M39: =SUM((M32-$O36)^2,(M33-$O36)^2,(M34-$O36)^2) -> 0.000342
O40: Manual measurement | Q40: Algorithm Results | R40: averages | S40: Percentage of correct answers | T40: Difference between manual measurement and algorithmic measurement. | V40: absolute percentage error volume (APE)
A41: Package Type | B41: Example of output from a valid test. | G41: Measurements Package 1 | N41: PCT4 Volume (m³) | O41: =0.51*0.16*0.155 -> 0.012648 | Q41: Execution time (s) | R41: =G48 -> 0.65
A42: Package 4 | B42: Object identified with 424 points. Total execution time: 0.57 seconds Object dimensions: Length: 0.523 m | Width: 0.189 m | Height: 0.145 m Dimensions (Convex Hull): Base area: 0.081 m² | Height: 0.145 m Total volume: 0.011683 m³ Successful attempt! Volume within the standard. | F42: Tests | G42: Time | H42: Volume | I42: Number of points | J42: Length | K42: Width | L42: Height | M42: TSD | N42: Length (m) | O42: 0.51 | Q42: Volume (m³) | R42: =H48 -> 0.01241825 | S42: =R42/O41 -> 0.98183507 | T42: =O41-R42 -> 0.00022975 | V42: =(ABS(H43-O41)/O41+ABS(H44-O41)/O41+ABS(H45-O41)/O41+ABS(H46-O41)/O41) -> 0.19679001
F43: 1 | G43: 0.57 | H43: 0.013433 | I43: 455 | J43: 0.449 | K43: 0.266 | L43: 0.144 | M43: =1.55-L43-0.1 -> 1.306 | N43: Width (m) | O43: 0.16 | Q43: Length (m) | R43: =J48 -> 0.491 | S43: =R43/O42 -> 0.9627451 | T43: =O42-R43 -> 0.019
F44: 2 | G44: 0.75 | H44: 0.012143 | I44: 490 | J44: 0.5 | K44: 0.196 | L44: 0.146 | M44: =1.55-L44-0.1 -> 1.304 | N44: Height (m) | O44: 0.155 | Q44: Width (m) | R44: =K48 -> 0.21666667 | S44: =R44/O43 -> 1.3541667 | T44: =O43-R44 -> -0.056666667
F45: 3 | G45: 0.71 | H45: 0.012414 | I45: 459 | J45: 0.524 | K45: 0.188 | L45: 0.147 | M45: =1.55-L45-0.1 -> 1.303 | N45: Top Sensor Distance (TSD) | O45: =1.55-O44-0.1 -> 1.295 | Q45: Height (m) | R45: =L48 -> 0.14566667 | S45: =R45/O44 -> 0.93978495 | T45: =O44-R45 -> 0.0093333333
F46: 4 | G46: 0.57 | H46: 0.011683 | I46: 424 | J46: 0.523 | K46: 0.189 | L46: 0.145 | M46: =1.55-L46-0.1 -> 1.305 | Q46: Number of points | R46: =I48 -> 457
F47: 5 | Q47: Top Sensor Distance (TSD) | R47: =M48 -> 1.3043333 | S47: =R47/O45 -> 1.0072072 | T47: =O45-R47 -> -0.0093333333
...

Sheet Voxelization
A2: Test sequence for calculating packet volume using voxelization
A6: Testing with the Voxelization Volume Estimation algorithm
A8: Package Type | B8: Example of output from a valid test. | G8: Measurements Package 1 | O8: Manual measurement (m) | Q8: Algorithm Results | R8: averages | S8: Percentage of correct answers | T8: Difference between manual measurement and algorithmic measurement. | V8: absolute percentage error volume (ACE)
A9: Package 1 | B9: Object identified with 1334 points. Total execution time: 2.70 seconds Dimensions (Voxelization): Length: 0.540 m | Width: 0.320 m | Height: 0.495 m Occupied voxels: 1289 | Voxel size: 0.010 m Estimated volume: 0.063816 m³ | F9: Tests | G9: Time | H9: Volume | I9: Number of points | J9: Length | K9: Width | L9: Height | M9: TSD | N9: VolumePCT1 (m³) | O9: =0.485*0.275*0.495 -> 0.066020625 | Q9: Execution time (s) | R9: =G15 -> 6.2133333
F10: 1 | G10: 3 | H10: 0.063348 | I10: 1393 | J10: 0.54 | K10: 0.33 | L10: 0.495 | M10: =1.55-L10-0.1 -> 0.955 | N10: Length (m) | O10: 0.485 | Q10: Volume (m³) | R10: =H15 -> 0.063874333 | S10: =R10/O9 -> 0.96749059 | T10: =O9-R10 -> 0.0021462917 | V10: =(ABS(H10-O9)/O9+ABS(H11-O9)/O9+ABS(H12-O9)/O9) -> 0.097528235
F11: 2 | G11: 2.7 | H11: 0.063816 | I11: 1334 | J11: 0.54 | K11: 0.32 | L11: 0.495 | M11: =1.55-L11-0.1 -> 0.955 | N11: Width (m) | O11: 0.275 | Q11: Length (m) | R11: =J15 -> 0.54 | S11: =R11/O10 -> 1.1134021 | T11: =O10-R11 -> -0.055
F12: 3 | G12: 12.94 | H12: 0.064459 | I12: 1346 | J12: 0.54 | K12: 0.32 | L12: 0.495 | M12: =1.55-L12-0.1 -> 0.955 | N12: Height (m) | O12: 0.5 | Q12: Width (m) | R12: =K15 -> 0.32333333 | S12: =R12/O11 -> 1.1757576 | T12: =O11-R12 -> -0.048333333
F13: 4 | N13: Top Sensor Distance (TSD) | O13: =1.55-O12-0.1 -> 0.95 | Q13: Height (m) | R13: =L15 -> 0.495 | S13: =R13/O12 -> 0.99 | T13: =O12-R13 -> 0.005
F14: 5 | Q14: Number of points | R14: =I15 -> 1357.6667
F15: average | G15: =AVERAGEA(G10:G13) -> 6.2133333 | H15: =AVERAGEA(H10:H13) -> 0.063874333 | I15: =AVERAGEA(I10:I13) -> 1357.6667 | J15: =AVERAGEA(J10:J13) -> 0.54 | K15: =AVERAGEA(K10:K13) -> 0.32333333 | L15: =AVERAGEA(L10:L13) -> 0.495 | M15: =AVERAGEA(M10:M13) -> 0.955 | Q15: Top Sensor Distance (TSD) | R15: =M15 -> 0.955 | S15: =R15/O13 -> 1.0052632 | T15: =O13-R15 -> -0.005
F16: Accuracy % | H16: =H15/O9 -> 0.96749059 | J16: =J15/O10 -> 1.1134021 | K16: =K15/O11 -> 1.1757576 | L16: =L15/O12 -> 0.99 | M16: =M15/O13 -> 1.0052632
F17: Error square | H17: =SUM((H10-O9)^2,(H11-O9)^2,(H12-O9)^2) -> 1.4441968e-05 | J17: =SUM((J10-$O10)^2,(J11-$O10)^2,(J12-$O10)^2) -> 0.009075 | K17: =SUM((K10-$O11)^2,(K11-$O11)^2,(K12-$O11)^2) -> 0.007075 | L17: =SUM((L10-$O12)^2,(L11-$O12)^2,(L12-$O12)^2) -> 7.5e-05 | M17: =SUM((M10-$O13)^2,(M11-$O13)^2,(M12-$O13)^2) -> 7.5e-05
A19: Package Type | B19: Example of output from a valid test. | G19: Measurements Package 2
A20: Package 2 | B20: Object identified with 1971 points. Total execution time: 4.34 seconds Dimensions (Voxelization): Length: 0.510 m | Width: 0.480 m | Height: 0.179 m Occupied voxels: 1902 | Voxel size: 0.010 m Estimated volume: 0.034008 m³ | F20: Tests | G20: Time | H20: Volume | I20: Number of points | J20: Length | K20: Width | L20: Height | M20: TSD
F21: 1 | G21: 5.76 | H21: 0.034379 | I21: 2039 | J21: 0.52 | K21: 0.49 | L21: 0.175 | M21: =1.55-L21-0.1 -> 1.275 | O21: Manual measurement | Q21: Algorithm Results | R21: averages | S21: Percentage of correct answers | T21: Difference between manual measurement and algorithmic measurement. | V21: absolute percentage error volume (ACE)
F22: 2 | G22: 7.02 | H22: 0.034176 | I22: 2004 | J22: 0.51 | K22: 0.48 | L22: 0.18 | M22: =1.55-L22-0.1 -> 1.27 | N22: PCT2 Volume (m2) | O22: =0.44*0.46*0.21 -> 0.042504 | Q22: Execution time (s) | R22: =G26 -> 5.7066667
F23: 3 | G23: 4.34 | H23: 0.034008 | I23: 1971 | J23: 0.51 | K23: 0.48 | L23: 0.179 | M23: =1.55-L23-0.1 -> 1.271 | N23: Length (m) | O23: 0.46 | Q23: Volume (m³) | R23: =H26 -> 0.034187667 | S23: =R23/O22 -> 0.80433998 | T23: =O22-R23 -> 0.0083163333 | V23: =(ABS(H21-O22)/O22+ABS(H22-O22)/O22+ABS(H23-O22)/O22) -> 0.58698005
F24: 4 | N24: Width (m) | O24: 0.44 | Q24: Length (m) | R24: =J26 -> 0.51333333 | S24: =R24/O23 -> 1.115942 | T24: =O23-R24 -> -0.053333333
F25: 5 | N25: Height (m) | O25: 0.21 | Q25: Width (m) | R25: =K26 -> 0.48333333 | S25: =R25/O24 -> 1.0984848 | T25: =O24-R25 -> -0.043333333
F26: average | G26: =AVERAGEA(G21:G24) -> 5.7066667 | H26: =AVERAGEA(H21:H24) -> 0.034187667 | I26: =AVERAGEA(I21:I24) -> 2004.6667 | J26: =AVERAGEA(J21:J23) -> 0.51333333 | K26: =AVERAGEA(K21:K23) -> 0.48333333 | L26: =AVERAGEA(L21:L23) -> 0.178 | M26: =AVERAGEA(M21:M23) -> 1.272 | N26: Top Sensor Distance (TSD) | O26: =1.55-O25-0.1 -> 1.24 | Q26: Height (m) | R26: =L26 -> 0.178 | S26: =R26/O25 -> 0.84761905 | T26: =O25-R26 -> 0.032
F27: Accuracy % | H27: =H26/O22 -> 0.80433998 | J27: =J26/O23 -> 1.115942 | K27: =K26/O24 -> 1.0984848 | L27: =L26/O25 -> 0.84761905 | M27: =M26/O26 -> 1.0258065 | Q27: Number of points | R27: =I26 -> 2004.6667
F28: Error square | H28: =SUM((H21-$O22)^2,(H22-$O22)^2,(H23-$O22)^2) -> 0.00020755322 | J28: =SUM((J21-$O23)^2,(J22-$O23)^2,(J23-$O23)^2) -> 0.0086 | K28: =SUM((K21-$O24)^2,(K22-$O24)^2,(K23-$O24)^2) -> 0.0057 | L28: =SUM((L21-$O25)^2,(L22-$O25)^2,(L23-$O25)^2) -> 0.003086 | M28: =SUM((M21-$O26)^2,(M22-$O26)^2,(M23-$O26)^2) -> 0.003086 | Q28: Top Sensor Distance (TSD) | R28: =M26 -> 1.272 | S28: =R28/O26 -> 1.0258065 | T28: =O26-R28 -> -0.032
A30: Package Type | B30: Example of output from a valid test. | G30: Measurements Package 3
A31: Package 3 | B31: Object identified with 2730 points. Total execution time: 10.54 seconds Dimensions (Voxelization): Length: 0.570 m | Width: 0.560 m | Height: 0.492 m Occupied voxels: 2600 | Voxel size: 0.010 m Estimated volume: 0.128023 m³ Successful attempt! Volume within the standard. | F31: Tests | G31: Time | H31: Volume | I31: Number of points | J31: Length | K31: Width | L31: Height | M31: TSD | O31: Manual measurement | Q31: Algorithm Results | R31: averages | S31: Percentage of correct answers | T31: Difference between manual measurement and algorithmic measurement. | V31: absolute percentage error volume (ACE)
F32: 1 | G32: 10.54 | H32: 0.128023 | I32: 2730 | J32: 0.57 | K32: 0.56 | L32: 0.492 | M32: =1.55-L32-0.1 -> 0.958 | N32: PCT3 Volume (m³) | O32: =0.505*0.505*0.505 -> 0.12878762 | Q32: Execution time (s) | R32: =G37 -> 11.743333
F33: 2 | G33: 13.43 | H33: 0.128036 | I33: 2757 | J33: 0.57 | K33: 0.55 | L33: 0.492 | M33: =1.55-L33-0.1 -> 0.958 | N33: Length (m) | O33: 0.505 | Q33: Volume (m³) | R33: =H37 -> 0.12800733 | S33: =R33/O32 -> 0.99394125 | T33: =O32-R33 -> 0.00078029167 | V33: =(ABS(H32-O32)/O32+ABS(H33-O32)/O32+ABS(H34-O32)/O32) -> 0.018176242
F34: 3 | G34: 11.26 | H34: 0.127963 | J34: 0.57 | K34: 0.55 | L34: 0.492 | M34: =1.55-L34-0.1 -> 0.958 | N34: Width (m) | O34: 0.505 | Q34: Length (m) | R34: =J37 -> 0.57 | S34: =R34/O33 -> 1.1287129 | T34: =O33-R34 -> -0.065
F35: 4 | N35: Height (m) | O35: 0.505 | Q35: Width (m) | R35: =K37 -> 0.55333333 | S35: =R35/O34 -> 1.0957096 | T35: =O34-R35 -> -0.048333333
F36: 5 | N36: Top Sensor Distance (TSD) | O36: =1.55-O35-0.1 -> 0.945 | Q36: Height (m) | R36: =L37 -> 0.492 | S36: =R36/O35 -> 0.97425743 | T36: =O35-R36 -> 0.013
F37: average | G37: =AVERAGEA(G32:G35) -> 11.743333 | H37: =AVERAGEA(H32:H35) -> 0.12800733 | I37: =AVERAGEA(I32:I35) -> 2743.5 | J37: =AVERAGEA(J32:J34) -> 0.57 | K37: =AVERAGEA(K32:K34) -> 0.55333333 | L37: =AVERAGEA(L32:L34) -> 0.492 | M37: =AVERAGEA(M32:M34) -> 0.958 | Q37: Number of points | R37: =I37 -> 2743.5
F38: Accuracy % | H38: =H37/O32 -> 0.99394125 | J38: =J37/O33 -> 1.1287129 | K38: =K37/O34 -> 1.0957096 | L38: =L37/O35 -> 0.97425743 | M38: =M37/O36 -> 1.0137566 | Q38: Top Sensor Distance (TSD) | R38: =M37 -> 0.958 | S38: =R38/O36 -> 1.0137566 | T38: =O36-R38 -> -0.013
F39: Error square | H39: =SUM((H32-O32)^2,(H33-O32)^2,(H34-O32)^2) -> 1.8295979e-06 | J39: =SUM((J32-$O33)^2,(J33-$O33)^2,(J34-$O33)^2) -> 0.012675 | K39: =SUM((K32-$O34)^2,(K33-$O34)^2,(K34-$O34)^2) -> 0.007075 | L39: =SUM((L32-$O35)^2,(L33-$O35)^2,(L34-$O35)^2) -> 0.000507 | M39: =SUM((M32-$O36)^2,(M33-$O36)^2,(M34-$O36)^2) -> 0.000507
O40: Manual measurement | Q40: Algorithm Results | R40: averages | S40: Percentage of correct answers | T40: Difference between manual measurement and algorithmic measurement. | V40: absolute percentage error volume (ACE)
A41: Package Type | B41: Example of output from a valid test. | G41: Measurements Package 4 | N41: PCT4 Volume (m³) | O41: =0.51*0.16*0.155 -> 0.012648 | Q41: Execution time (s) | R41: =G48 -> 5.3433333
A42: Package 4 | B42: Object identified with 852 points. Total execution time: 1.28 seconds Dimensions (Voxelization): Length: 0.540 m | Width: 0.280 m | Height: 0.147 m Occupied voxels: 816 | Voxel size: 0.010 m Estimated volume: 0.012001 m³ Successful attempt! Volume within the standard. | F42: Tests | G42: Time | H42: Volume | I42: Number of points | J42: Length | K42: Width | L42: Height | M42: TSD | N42: Length (m) | O42: 0.51 | Q42: Volume (m³) | R42: =H48 -> 0.012085 | S42: =R42/O41 -> 0.95548703 | T42: =O41-R42 -> 0.000563 | V42: =(ABS(H43-O41)/O41+ABS(H44-O41)/O41+ABS(H45-O41)/O41) -> 0.1335389
F43: 1 | G43: 1.28 | H43: 0.012001 | I43: 852 | J43: 0.54 | K43: 0.28 | L43: 0.147 | M43: =1.55-L43-0.1 -> 1.303 | N43: Width (m) | O43: 0.16 | Q43: Length (m) | R43: =J48 -> 0.54 | S43: =R43/O42 -> 1.0588235 | T43: =O42-R43 -> -0.03
F44: 2 | G44: 1.3 | H44: 0.011919 | I44: 836 | J44: 0.54 | K44: 0.28 | L44: 0.148 | M44: =1.55-L44-0.1 -> 1.302 | N44: Height (m) | O44: 0.155 | Q44: Width (m) | R44: =K48 -> 0.28 | S44: =R44/O43 -> 1.75 | T44: =O43-R44 -> -0.12
F45: 3 | G45: 13.45 | H45: 0.012335 | I45: 862 | J45: 0.54 | K45: 0.28 | L45: 0.149 | M45: =1.55-L45-0.1 -> 1.301 | N45: Top Sensor Distance (TSD) | O45: =1.55-O44-0.1 -> 1.295 | Q45: Height (m) | R45: =L48 -> 0.148 | S45: =R45/O44 -> 0.95483871 | T45: =O44-R45 -> 0.007
F46: 4 | Q46: Number of points | R46: =I48 -> 850
F47: 5 | Q47: Top Sensor Distance (TSD) | R47: =M48 -> 1.302 | S47: =R47/O45 -> 1.0054054 | T47: =O45-R47 -> -0.007
...
